Workbook

Sheet Dashboard
A1: Operational Data Analysis Dashboard
A2: Excel workbook | Dataset: Olist Brazilian E-Commerce Public Dataset | Analysis focus: delivery performance, delay patterns, and process improvement | R2: Month | S2: Delay Rate (%) | T2: State | U2: Delay Rate (%) | V2: Category | W2: Delay Rate (%) | X2: Status | Y2: Orders
R3: 2016-10 | S3: 1.1320755 | T3: SP | U3: 5.8947004 | V3: Audio | W3: 13.081395 | X3: On Time | Y3: 88644
A4: Total Delivered Orders | B4: =SUM(Monthly_Analysis!B4:B26) -> 96470 | C4: Delay Rate | D4: =SUM(Monthly_Analysis!D4:D26)/SUM(Monthly_Analysis!B4:B26) -> 0.081123665 | E4: Avg Delivery Days | F4: =SUMPRODUCT(Monthly_Analysis!B4:B26,Monthly_Analysis!F4:F26)/SUM(Monthly_Analysis!B4:B26) -> 12.558217 | G4: Avg Review Score | H4: =AVERAGE(Monthly_Analysis!H4:H26) -> 4.0652973 | R4: 2017-01 | S4: 3.0666667 | T4: RJ | U4: 13.473684 | V4: Books Technical | W4: 10.980392 | X4: Delayed | Y4: 7826
R5: 2017-02 | S5: 3.2062916 | T5: MG | U5: 5.6103576 | V5: Home Confort | W5: 10.354223
R6: 2017-03 | S6: 5.5773763 | T6: BA | U6: 14.035627 | V6: Food | W6: 10.091743
A7: Delayed Orders | B7: =SUM(Monthly_Analysis!D4:D26) -> 7826 | C7: On-Time Orders | D7: =SUM(Monthly_Analysis!C4:C26) -> 88644 | E7: Avg Delay Days | F7: =SUMPRODUCT(Monthly_Analysis!B4:B26,Monthly_Analysis!G4:G26)/SUM(Monthly_Analysis!B4:B26) -> 0.77487507 | G7: Avg Freight Cost | H7: =SUMPRODUCT(Monthly_Analysis!B4:B26,Monthly_Analysis!I4:I26)/SUM(Monthly_Analysis!B4:B26) -> 22.785798 | R7: 2017-04 | S7: 7.8593139 | T7: RS | U7: 7.1482036 | V7: Electronics | W7: 9.8524132
R8: 2017-05 | S8: 3.6107193 | T8: SC | U8: 9.7574732 | V8: Baby | W8: 9.3342981
R9: 2017-06 | S9: 3.8596491 | T9: PR | U9: 4.9969531 | V9: Office Furniture | W9: 9.2295345
A10: Key Finding | B10: Evidence from analysis | C10: Operational impact | D10: Suggested action | R10: 2017-07 | S10: 3.4349174 | T10: ES | U10: 12.230576 | V10: Construction Tools Construction | W10: 9.215956
A11: Delay risk is concentrated in specific states. | B11: Overall delay rate is approximately 8.1%, with RJ and BA showing higher delay rates than SP and MG. | C11: Delays are not evenly distributed, so a general fix would be less effective. | D11: Prioritize state-level delivery monitoring and route exception reviews. | R11: 2017-08 | S11: 3.3150489 | T11: CE | U11: 15.324472 | V11: Construction Tools Lights | W11: 9.0517241
A12: Long-distance/last-mile phases appear to drive many late orders. | B12: States with longer average delivery days also show weaker review scores and higher delay rates. | C12: Customer satisfaction may fall when delivery dates are missed. | D12: Create weekly delay dashboards and escalation triggers. | R12: 2017-09 | S12: 5.2048193 | T12: PE | U12: 10.797238 | V12: Health Beauty | W12: 8.989547
A13: Some product categories have higher delay rates. | B13: Audio, Home Comfort, Electronics, and Food show elevated delay rates among categories with meaningful volume. | C13: Category handling, packaging, or carrier requirements may create bottlenecks. | D13: Review category-specific packing standards, supplier readiness, and carrier SLAs. | R13: 2017-10 | S13: 5.2925413
A14: Review scores can be used as an operational quality signal. | B14: Lower review scores are more visible in areas with higher delay rates. | C14: Operations issues may become customer experience issues quickly. | D14: Track review score alongside delivery KPIs, not only sales/order volume. | R14: 2017-11 | S14: 14.311196
R15: 2017-12 | S15: 8.3801923
R16: 2018-01 | S16: 6.5638704
R17: 2018-02 | S17: 15.987796
R18: 2018-03 | S18: 21.362273
R19: 2018-04 | S19: 5.3103854
R20: 2018-05 | S20: 8.2382575
R21: 2018-06 | S21: 1.3615486
R22: 2018-07 | S22: 4.4834308
R23: 2018-08 | S23: 10.392064

Sheet Raw_Data_Sample
A1: Order_ID | B1: Purchase_Date | C1: Approved_Date | D1: Carrier_Date | E1: Delivered_Date | F1: Estimated_Date | G1: State | H1: City | I1: Product_Category | J1: Items | K1: Product_Value | L1: Freight_Value | M1: Review_Score | N1: Delivery_Days | O1: Delay_Days | P1: Delay_Status | Q1: Approval_Hours | R1: Warehouse_Handling_Days | S1: Last_Mile_Days | T1: SLA_Bucket | U1: Exception_Flag | V1: Source_URL
A2: 35d3a51724a47ef1d0b89911e39cc4ff | B2: 42647.6 | C2: 42648.114 | D2: 42657.114 | E2: 42669.628 | F2: 42724 | G2: RS | H2: Santa Cruz Do Sul | I2: Furniture Decor | J2: 1 | K2: 39.99 | L2: 22.34 | M2: 5 | N2: =IFERROR(E2-B2,"") -> 22.027801 | O2: =IFERROR(MAX(0,E2-F2),"") -> 0 | P2: =IF(O2>0,"Delayed","On Time") -> On Time | Q2: =IFERROR((C2-B2)*24,"") -> 12.344167 | R2: =IFERROR(D2-C2,"") -> 9.0000116 | S2: =IFERROR(E2-D2,"") -> 12.513449 | T2: =IF(O2=0,"On Time/Early",IF(O2<=3,"1-3 Days Late",IF(O2<=7,"4-7 Days Late","8+ Days Late"))) -> On Time/Early | U2: =IF(P2="Delayed","Needs Review","Normal") -> Normal | V2: https://www.kaggle.com/datasets/olistbr/brazilian-ecommerce
A3: 985db56d4cabd2577d0960194dd2cd5a | B3: 42647.65 | C3: 42649.665 | D3: 42664.69 | E3: 42671.628 | F3: 42704 | G3: MG | H3: Belo Horizonte | I3: Health Beauty | J3: 1 | K3: 136.9 | L3: 17.39 | M3: 5 | N3: =IFERROR(E3-B3,"") -> 23.977928 | O3: =IFERROR(MAX(0,E3-F3),"") -> 0 | P3: =IF(O3>0,"Delayed","On Time") -> On Time | Q3: =IFERROR((C3-B3)*24,"") -> 48.360556 | R3: =IFERROR(D3-C3,"") -> 15.025475 | S3: =IFERROR(E3-D3,"") -> 6.9374306 | T3: =IF(O3=0,"On Time/Early",IF(O3<=3,"1-3 Days Late",IF(O3<=7,"4-7 Days Late","8+ Days Late"))) -> On Time/Early | U3: =IF(P3="Delayed","Needs Review","Normal") -> Normal | V3: https://www.kaggle.com/datasets/olistbr/brazilian-ecommerce
A4: a9fc3ae13c740ad46532fd50b61c69d5 | B4: 42647.947 | C4: 42649.656 | D4: 42653.656 | E4: 42656.656 | F4: 42702 | G4: MG | H4: Caetanopolis | I4: Furniture Decor | J4: 1 | K4: 19.9 | L4: 14.52 | M4: 5 | N4: =IFERROR(E4-B4,"") -> 8.7093056 | O4: =IFERROR(MAX(0,E4-F4),"") -> 0 | P4: =IF(O4>0,"Delayed","On Time") -> On Time | Q4: =IFERROR((C4-B4)*24,"") -> 41.023056 | R4: =IFERROR(D4-C4,"") -> 4.0000116 | S4: =IFERROR(E4-D4,"") -> 3 | T4: =IF(O4=0,"On Time/Early",IF(O4<=3,"1-3 Days Late",IF(O4<=7,"4-7 Days Late","8+ Days Late"))) -> On Time/Early | U4: =IF(P4="Delayed","Needs Review","Normal") -> Normal | V4: https://www.kaggle.com/datasets/olistbr/brazilian-ecommerce
A5: f31853a4f30d4851c847e4494663e749 | B5: 42649.515 | C5: 42649.599 | D5: 42658.536 | E5: 42667.872 | F5: 42704 | G5: SP | H5: Praia Grande | I5: Baby | J5: 1 | K5: 159.9 | L5: 16.33 | M5: 2 | N5: =IFERROR(E5-B5,"") -> 18.356829 | O5: =IFERROR(MAX(0,E5-F5),"") -> 0 | P5: =IF(O5>0,"Delayed","On Time") -> On Time | Q5: =IFERROR((C5-B5)*24,"") -> 2.0022222 | R5: =IFERROR(D5-C5,"") -> 8.9378009 | S5: =IFERROR(E5-D5,"") -> 9.3356019 | T5: =IF(O5=0,"On Time/Early",IF(O5<=3,"1-3 Days Late",IF(O5<=7,"4-7 Days Late","8+ Days Late"))) -> On Time/Early | U5: =IF(P5="Delayed","Needs Review","Normal") -> Normal | V5: https://www.kaggle.com/datasets/olistbr/brazilian-ecommerce
A6: 3d58fd1ee438a43f2a826dda6b013519 | B6: 42649.815 | C6: 42650.426 | D6: 42664.682 | E6: 42667.682 | F6: 42710 | G6: GO | H6: Goiania | I6: Toys | J6: 1 | K6: 41.99 | L6: 19.07 | M6: 5 | N6: =IFERROR(E6-B6,"") -> 17.866933 | O6: =IFERROR(MAX(0,E6-F6),"") -> 0 | P6: =IF(O6>0,"Delayed","On Time") -> On Time | Q6: =IFERROR((C6-B6)*24,"") -> 14.661667 | R6: =IFERROR(D6-C6,"") -> 14.25603 | S6: =IFERROR(E6-D6,"") -> 3 | T6: =IF(O6=0,"On Time/Early",IF(O6<=3,"1-3 Days Late",IF(O6<=7,"4-7 Days Late","8+ Days Late"))) -> On Time/Early | U6: =IF(P6="Delayed","Needs Review","Normal") -> Normal | V6: https://www.kaggle.com/datasets/olistbr/brazilian-ecommerce
A7: e6db6e9529fecbe14cd05dd349816656 | B7: 42741.894 | C7: 42741.9 | D7: 42744.506 | E7: 42748.582 | F7: 42786 | G7: MG | H7: Lagoa Santa | I7: Consoles Games | J7: 1 | K7: 109.9 | L7: 14.94 | M7: 4 | N7: =IFERROR(E7-B7,"") -> 6.6872685 | O7: =IFERROR(MAX(0,E7-F7),"") -> 0 | P7: =IF(O7>0,"Delayed","On Time") -> On Time | Q7: =IFERROR((C7-B7)*24,"") -> 0.12527778 | R7: =IFERROR(D7-C7,"") -> 2.606412 | S7: =IFERROR(E7-D7,"") -> 4.0756366 | T7: =IF(O7=0,"On Time/Early",IF(O7<=3,"1-3 Days Late",IF(O7<=7,"4-7 Days Late","8+ Days Late"))) -> On Time/Early | U7: =IF(P7="Delayed","Needs Review","Normal") -> Normal | V7: https://www.kaggle.com/datasets/olistbr/brazilian-ecommerce
A8: 22266e2f8d8084cd2b5d8488164d043a | B8: 42750.001 | C8: 42750.011 | D8: 42751.279 | E8: 42758.576 | F8: 42790 | G8: MG | H8: Itajuba | I8: Telephony | J8: 2 | K8: 20.98 | L8: 29.04 | M8: 4 | N8: =IFERROR(E8-B8,"") -> 8.574537 | O8: =IFERROR(MAX(0,E8-F8),"") -> 0 | P8: =IF(O8>0,"Delayed","On Time") -> On Time | Q8: =IFERROR((C8-B8)*24,"") -> 0.23222222 | R8: =IFERROR(D8-C8,"") -> 1.2684954 | S8: =IFERROR(E8-D8,"") -> 7.2963657 | T8: =IF(O8=0,"On Time/Early",IF(O8<=3,"1-3 Days Late",IF(O8<=7,"4-7 Days Late","8+ Days Late"))) -> On Time/Early | U8: =IF(P8="Delayed","Needs Review","Normal") -> Normal | V8: https://www.kaggle.com/datasets/olistbr/brazilian-ecommerce
A9: 3a6cac3e6717e6a7ee4cb28aaa149a91 | B9: 42753.843 | C9: 42753.851 | D9: 42755.464 | E9: 42762.718 | F9: 42786 | G9: MG | H9: Belo Horizonte | I9: Computers Accessories | J9: 1 | K9: 199.9 | L9: 19.99 | M9: 5 | N9: =IFERROR(E9-B9,"") -> 8.8750231 | O9: =IFERROR(MAX(0,E9-F9),"") -> 0 | P9: =IF(O9>0,"Delayed","On Time") -> On Time | Q9: =IFERROR((C9-B9)*24,"") -> 0.18194444 | R9: =IFERROR(D9-C9,"") -> 1.6129282 | S9: =IFERROR(E9-D9,"") -> 7.2545139 | T9: =IF(O9=0,"On Time/Early",IF(O9<=3,"1-3 Days Late",IF(O9<=7,"4-7 Days Late","8+ Days Late"))) -> On Time/Early | U9: =IF(P9="Delayed","Needs Review","Normal") -> Normal | V9: https://www.kaggle.com/datasets/olistbr/brazilian-ecommerce
A10: b49998737b7359ebe1b64b0b7ffb20f6 | B10: 42755.686 | C10: 42755.696 | D10: 42758.463 | E10: 42761.683 | F10: 42795 | G10: MG | H10: Monte Carmelo | I10: Cool Stuff | J10: 1 | K10: 22.3 | L10: 14.52 | M10: 4 | N10: =IFERROR(E10-B10,"") -> 5.9976505 | O10: =IFERROR(MAX(0,E10-F10),"") -> 0 | P10: =IF(O10>0,"Delayed","On Time") -> On Time | Q10: =IFERROR((C10-B10)*24,"") -> 0.24166667 | R10: =IFERROR(D10-C10,"") -> 2.7670833 | S10: =IFERROR(E10-D10,"") -> 3.2204977 | T10: =IF(O10=0,"On Time/Early",IF(O10<=3,"1-3 Days Late",IF(O10<=7,"4-7 Days Late","8+ Days Late"))) -> On Time/Early | U10: =IF(P10="Delayed","Needs Review","Normal") -> Normal | V10: https://www.kaggle.com/datasets/olistbr/brazilian-ecommerce
A11: 9786c52ca3e1ed1ef3ba5c65941627f0 | B11: 42756.883 | C11: 42757.897 | D11: 42761.465 | E11: 42775.607 | F11: 42815 | G11: PE | H11: Camaragibe | I11: Furniture Decor | J11: 1 | K11: 119.9 | L11: 50 | M11: 5 | N11: =IFERROR(E11-B11,"") -> 18.7239 | O11: =IFERROR(MAX(0,E11-F11),"") -> 0 | P11: =IF(O11>0,"Delayed","On Time") -> On Time | Q11: =IFERROR((C11-B11)*24,"") -> 24.321944 | R11: =IFERROR(D11-C11,"") -> 3.5682292 | S11: =IFERROR(E11-D11,"") -> 14.142257 | T11: =IF(O11=0,"On Time/Early",IF(O11<=3,"1-3 Days Late",IF(O11<=7,"4-7 Days Late","8+ Days Late"))) -> On Time/Early | U11: =IF(P11="Delayed","Needs Review","Normal") -> Normal | V11: https://www.kaggle.com/datasets/olistbr/brazilian-ecommerce
A12: b9581bf1b646f4fc021b131e1ca4d034 | B12: 42760.949 | C12: 42760.96 | D12: 42761.57 | E12: 42774.393 | F12: 42788 | G12: MG | H12: Itabira | I12: Garden Tools | J12: 1 | K12: 61.9 | L12: 15.64 | M12: 2 | N12: =IFERROR(E12-B12,"") -> 13.444178 | O12: =IFERROR(MAX(0,E12-F12),"") -> 0 | P12: =IF(O12>0,"Delayed","On Time") -> On Time | Q12: =IFERROR((C12-B12)*24,"") -> 0.26361111 | R12: =IFERROR(D12-C12,"") -> 0.61050926 | S12: =IFERROR(E12-D12,"") -> 12.822685 | T12: =IF(O12=0,"On Time/Early",IF(O12<=3,"1-3 Days Late",IF(O12<=7,"4-7 Days Late","8+ Days Late"))) -> On Time/Early | U12: =IF(P12="Delayed","Needs Review","Normal") -> Normal | V12: https://www.kaggle.com/datasets/olistbr/brazilian-ecommerce
A13: aa04ef5214580b06b10e2a378300db44 | B13: 42762.021 | C13: 42762.045 | D13: 42765.486 | E13: 42773.552 | F13: 42811 | G13: MG | H13: Divinopolis | I13: Health Beauty | J13: 1 | K13: 370 | L13: 19.43 | M13: 5 | N13: =IFERROR(E13-B13,"") -> 11.531505 | O13: =IFERROR(MAX(0,E13-F13),"") -> 0 | P13: =IF(O13>0,"Delayed","On Time") -> On Time | Q13: =IFERROR((C13-B13)*24,"") -> 0.58944444 | R13: =IFERROR(D13-C13,"") -> 3.4408681 | S13: =IFERROR(E13-D13,"") -> 8.0660764 | T13: =IF(O13=0,"On Time/Early",IF(O13<=3,"1-3 Days Late",IF(O13<=7,"4-7 Days Late","8+ Days Late"))) -> On Time/Early | U13: =IF(P13="Delayed","Needs Review","Normal") -> Normal | V13: https://www.kaggle.com/datasets/olistbr/brazilian-ecommerce
... A171: 9c9e682bee9157ebdd3875801b35e626 | B171: 42866.616 | C171: 42866.622 | D171: 42867.445 | E171: 42870.287 | F171: 42874 | G171: SP | H171: Sao Paulo | I171: Fixed Telephony | J171: 1 | K171: 39.99 | L171: 7.78 | M171: 5 | N171: =IFERROR(E171-B171,"") -> 3.6710417 | O171: =IFERROR(MAX(0,E171-F171),"") -> 0 | P171: =IF(O171>0,"Delayed","On Time") -> On Time | Q171: =IFERROR((C171-B171)*24,"") -> 0.13055556 | R171: =IFERROR(D171-C171,"") -> 0.82359954 | S171: =IFERROR(E171-D171,"") -> 2.8420023 | T171: =IF(O171=0,"On Time/Early",IF(O171<=3,"1-3 Days Late",IF(O171<=7,"4-7 Days Late","8+ Days Late"))) -> On Time/Early | U171: =IF(P171="Delayed","Needs Review","Normal") -> Normal | V171: https://www.kaggle.com/datasets/olistbr/brazilian-ecommerce
A172: 8a5631237c1d8626971f2867b25c076e | B172: 42866.62 | C172: 42867.627 | D172: 42870.582 | E172: 42878.492 | F172: 42886 | G172: ES | H172: Cariacica | I172: Tablets Printing Image | J172: 1 | K172: 889.99 | L172: 22.8 | N172: =IFERROR(E172-B172,"") -> 11.872049 | O172: =IFERROR(MAX(0,E172-F172),"") -> 0 | P172: =IF(O172>0,"Delayed","On Time") -> On Time | Q172: =IFERROR((C172-B172)*24,"") -> 24.175 | R172: =IFERROR(D172-C172,"") -> 2.9553356 | S172: =IFERROR(E172-D172,"") -> 7.9094213 | T172: =IF(O172=0,"On Time/Early",IF(O172<=3,"1-3 Days Late",IF(O172<=7,"4-7 Days Late","8+ Days Late"))) -> On Time/Early | U172: =IF(P172="Delayed","Needs Review","Normal") -> Normal | V172: https://www.kaggle.com/datasets/olistbr/brazilian-ecommerce
A173: 24014414a15d7274cad8a2917fe1f040 | B173: 42866.73 | C173: 42867.566 | D173: 42870.365 | E173: 42878.462 | F173: 42886 | G173: RJ | H173: Rio De Janeiro | I173: Health Beauty | J173: 2 | K173: 1308 | L173: 40.67 | M173: 5 | N173: =IFERROR(E173-B173,"") -> 11.732083 | O173: =IFERROR(MAX(0,E173-F173),"") -> 0 | P173: =IF(O173>0,"Delayed","On Time") -> On Time | Q173: =IFERROR((C173-B173)*24,"") -> 20.078056 | R173: =IFERROR(D173-C173,"") -> 2.7990856 | S173: =IFERROR(E173-D173,"") -> 8.096412 | T173: =IF(O173=0,"On Time/Early",IF(O173<=3,"1-3 Days Late",IF(O173<=7,"4-7 Days Late","8+ Days Late"))) -> On Time/Early | U173: =IF(P173="Delayed","Needs Review","Normal") -> Normal | V173: https://www.kaggle.com/datasets/olistbr/brazilian-ecommerce
A174: 26526add9da95bea7b977eff1d40d11b | B174: 42866.968 | C174: 42866.974 | D174: 42867.622 | E174: 42879.617 | F174: 42886 | G174: MG | H174: Januaria | I174: Telephony | J174: 1 | K174: 18.99 | L174: 15.1 | M174: 5 | N174: =IFERROR(E174-B174,"") -> 12.649641 | O174: =IFERROR(MAX(0,E174-F174),"") -> 0 | P174: =IF(O174>0,"Delayed","On Time") -> On Time | Q174: =IFERROR((C174-B174)*24,"") -> 0.15 | R174: =IFERROR(D174-C174,"") -> 0.6480787 | S174: =IFERROR(E174-D174,"") -> 11.995312 | T174: =IF(O174=0,"On Time/Early",IF(O174<=3,"1-3 Days Late",IF(O174<=7,"4-7 Days Late","8+ Days Late"))) -> On Time/Early | U174: =IF(P174="Delayed","Needs Review","Normal") -> Normal | V174: https://www.kaggle.com/datasets/olistbr/brazilian-ecommerce
A175: 8e337e3b4df76fa95a5e03ba9675cb56 | B175: 42867.935 | C175: 42867.941 | D175: 42871.668 | E175: 42877.37 | F175: 42886 | G175: SP | H175: Sao Paulo | I175: Bed Bath Table | J175: 2 | K175: 179.8 | L175: 24.26 | M175: 2 | N175: =IFERROR(E175-B175,"") -> 9.4343171 | O175: =IFERROR(MAX(0,E175-F175),"") -> 0 | P175: =IF(O175>0,"Delayed","On Time") -> On Time | Q175: =IFERROR((C175-B175)*24,"") -> 0.13888889 | R175: =IFERROR(D175-C175,"") -> 3.7271412 | S175: =IFERROR(E175-D175,"") -> 5.7013889 | T175: =IF(O175=0,"On Time/Early",IF(O175<=3,"1-3 Days Late",IF(O175<=7,"4-7 Days Late","8+ Days Late"))) -> On Time/Early | U175: =IF(P175="Delayed","Needs Review","Normal") -> Normal | V175: https://www.kaggle.com/datasets/olistbr/brazilian-ecommerce
A176: 193714aa21ead814cca06d425c299360 | B176: 42868.697 | C176: 42868.705 | D176: 42873.604 | E176: 42881.544 | F176: 42881 | G176: SP | H176: Jundiai | I176: Sports Leisure | J176: 1 | K176: 140 | L176: 13.54 | M176: 3 | N176: =IFERROR(E176-B176,"") -> 12.846887 | O176: =IFERROR(MAX(0,E176-F176),"") -> 0.54393519 | P176: =IF(O176>0,"Delayed","On Time") -> Delayed | Q176: =IFERROR((C176-B176)*24,"") -> 0.19194444 | R176: =IFERROR(D176-C176,"") -> 4.8986458 | S176: =IFERROR(E176-D176,"") -> 7.9402431 | T176: =IF(O176=0,"On Time/Early",IF(O176<=3,"1-3 Days Late",IF(O176<=7,"4-7 Days Late","8+ Days Late"))) -> 1-3 Days Late | U176: =IF(P176="Delayed","Needs Review","Normal") -> Needs Review | V176: https://www.kaggle.com/datasets/olistbr/brazilian-ecommerce
A177: 651bd7286b2e17e1e3ea7b644870e429 | B177: 42868.738 | C177: 42869.275 | D177: 42872.397 | E177: 42878.021 | F177: 42893 | G177: SP | H177: Ribeirao Preto | I177: Toys | J177: 1 | K177: 239 | L177: 14.01 | M177: 1 | N177: =IFERROR(E177-B177,"") -> 9.2829398 | O177: =IFERROR(MAX(0,E177-F177),"") -> 0 | P177: =IF(O177>0,"Delayed","On Time") -> On Time | Q177: =IFERROR((C177-B177)*24,"") -> 12.878056 | R177: =IFERROR(D177-C177,"") -> 3.1228588 | S177: =IFERROR(E177-D177,"") -> 5.6234954 | T177: =IF(O177=0,"On Time/Early",IF(O177<=3,"1-3 Days Late",IF(O177<=7,"4-7 Days Late","8+ Days Late"))) -> On Time/Early | U177: =IF(P177="Delayed","Needs Review","Normal") -> Normal | V177: https://www.kaggle.com/datasets/olistbr/brazilian-ecommerce
A178: 0168a7f186c1f066748d15d8c51f489a | B178: 42868.76 | C178: 42871.143 | D178: 42872.494 | E178: 42873.429 | F178: 42879 | G178: SP | H178: Suzano | I178: Housewares | J178: 1 | K178: 149.9 | L178: 8.3 | M178: 4 | N178: =IFERROR(E178-B178,"") -> 4.6689583 | O178: =IFERROR(MAX(0,E178-F178),"") -> 0 | P178: =IF(O178>0,"Delayed","On Time") -> On Time | Q178: =IFERROR((C178-B178)*24,"") -> 57.175556 | R178: =IFERROR(D178-C178,"") -> 1.3511574 | S178: =IFERROR(E178-D178,"") -> 0.93548611 | T178: =IF(O178=0,"On Time/Early",IF(O178<=3,"1-3 Days Late",IF(O178<=7,"4-7 Days Late","8+ Days Late"))) -> On Time/Early | U178: =IF(P178="Delayed","Needs Review","Normal") -> Normal | V178: https://www.kaggle.com/datasets/olistbr/brazilian-ecommerce
A179: 001d8f0e34a38c37f7dba2a37d4eba8b | B179: 42869.722 | C179: 42869.733 | D179: 42879.656 | E179: 42881.552 | F179: 42879 | G179: SP | H179: Sao Paulo | I179: Health Beauty | J179: 2 | K179: 37.98 | L179: 15.56 | M179: 1 | N179: =IFERROR(E179-B179,"") -> 11.829931 | O179: =IFERROR(MAX(0,E179-F179),"") -> 2.5519676 | P179: =IF(O179>0,"Delayed","On Time") -> Delayed | Q179: =IFERROR((C179-B179)*24,"") -> 0.2575 | R179: =IFERROR(D179-C179,"") -> 9.9234954 | S179: =IFERROR(E179-D179,"") -> 1.895706 | T179: =IF(O179=0,"On Time/Early",IF(O179<=3,"1-3 Days Late",IF(O179<=7,"4-7 Days Late","8+ Days Late"))) -> 1-3 Days Late | U179: =IF(P179="Delayed","Needs Review","Normal") -> Needs Review | V179: https://www.kaggle.com/datasets/olistbr/brazilian-ecommerce
A180: fd2b4179de3cceb73bc884f6c19d85d0 | B180: 42869.773 | C180: 42869.781 | D180: 42874.471 | E180: 42885.527 | F180: 42899 | G180: DF | H180: Brasilia | I180: Auto | J180: 1 | K180: 31.99 | L180: 34.15 | M180: 5 | N180: =IFERROR(E180-B180,"") -> 15.753137 | O180: =IFERROR(MAX(0,E180-F180),"") -> 0 | P180: =IF(O180>0,"Delayed","On Time") -> On Time | Q180: =IFERROR((C180-B180)*24,"") -> 0.19055556 | R180: =IFERROR(D180-C180,"") -> 4.689375 | S180: =IFERROR(E180-D180,"") -> 11.055822 | T180: =IF(O180=0,"On Time/Early",IF(O180<=3,"1-3 Days Late",IF(O180<=7,"4-7 Days Late","8+ Days Late"))) -> On Time/Early | U180: =IF(P180="Delayed","Needs Review","Normal") -> Normal | V180: https://www.kaggle.com/datasets/olistbr/brazilian-ecommerce
A181: d7520dd6301787392e59dddbbc68ea22 | B181: 42869.804 | C181: 42870.809 | D181: 42873.551 | E181: 42877.379 | F181: 42879 | G181: SP | H181: Sao Paulo | I181: Cool Stuff | J181: 1 | K181: 39.9 | L181: 8.72 | M181: 5 | N181: =IFERROR(E181-B181,"") -> 7.574213 | O181: =IFERROR(MAX(0,E181-F181),"") -> 0 | P181: =IF(O181>0,"Delayed","On Time") -> On Time | Q181: =IFERROR((C181-B181)*24,"") -> 24.118611 | R181: =IFERROR(D181-C181,"") -> 2.7414236 | S181: =IFERROR(E181-D181,"") -> 3.8278472 | T181: =IF(O181=0,"On Time/Early",IF(O181<=3,"1-3 Days Late",IF(O181<=7,"4-7 Days Late","8+ Days Late"))) -> On Time/Early | U181: =IF(P181="Delayed","Needs Review","Normal") -> Normal | V181: https://www.kaggle.com/datasets/olistbr/brazilian-ecommerce
A182: 6607ca536882b974ea594bc640b01519 | B182: 42869.875 | C182: 42869.882 | D182: 42872.287 | E182: 42877.554 | F182: 42886 | G182: SP | H182: Sao Paulo | I182: Bed Bath Table | J182: 1 | K182: 139.9 | L182: 14 | N182: =IFERROR(E182-B182,"") -> 7.6786458 | O182: =IFERROR(MAX(0,E182-F182),"") -> 0 | P182: =IF(O182>0,"Delayed","On Time") -> On Time | Q182: =IFERROR((C182-B182)*24,"") -> 0.16055556 | R182: =IFERROR(D182-C182,"") -> 2.404375 | S182: =IFERROR(E182-D182,"") -> 5.267581 | T182: =IF(O182=0,"On Time/Early",IF(O182<=3,"1-3 Days Late",IF(O182<=7,"4-7 Days Late","8+ Days Late"))) -> On Time/Early | U182: =IF(P182="Delayed","Needs Review","Normal") -> Normal | V182: https://www.kaggle.com/datasets/olistbr/brazilian-ecommerce
A183: 22f469f96aaa1fdd00d0ac66369a950f | B183: 42869.914 | C183: 42869.924 | D183: 42872.443 | E183: 42879.644 | F183: 42888 | G183: SP | H183: Ubatuba | I183: Watches Gifts | J183: 1 | K183: 52.5 | L183: 15.12 | M183: 4 | N183: =IFERROR(E183-B183,"") -> 9.7304514 | O183: =IFERROR(MAX(0,E183-F183),"") -> 0 | P183: =IF(O183>0,"Delayed","On Time") -> On Time | Q183: =IFERROR((C183-B183)*24,"") -> 0.23416667 | R183: =IFERROR(D183-C183,"") -> 2.5190046 | S183: =IFERROR(E183-D183,"") -> 7.2016898 | T183: =IF(O183=0,"On Time/Early",IF(O183<=3,"1-3 Days Late",IF(O183<=7,"4-7 Days Late","8+ Days Late"))) -> On Time/Early | U183: =IF(P183="Delayed","Needs Review","Normal") -> Normal | V183: https://www.kaggle.com/datasets/olistbr/brazilian-ecommerce
A184: ca91862f94f3eb805b394ae462b669a6 | B184: 42870.041 | C184: 42870.049 | D184: 42872.607 | E184: 42873.523 | F184: 42879 | G184: SP | H184: Sao Paulo | I184: Telephony | J184: 2 | K184: 59.98 | L184: 15.56 | M184: 5 | N184: =IFERROR(E184-B184,"") -> 3.4818866 | O184: =IFERROR(MAX(0,E184-F184),"") -> 0 | P184: =IF(O184>0,"Delayed","On Time") -> On Time | Q184: =IFERROR((C184-B184)*24,"") -> 0.17472222 | R184: =IFERROR(D184-C184,"") -> 2.5578588 | S184: =IFERROR(E184-D184,"") -> 0.91674769 | T184: =IF(O184=0,"On Time/Early",IF(O184<=3,"1-3 Days Late",IF(O184<=7,"4-7 Days Late","8+ Days Late"))) -> On Time/Early | U184: =IF(P184="Delayed","Needs Review","Normal") -> Normal | V184: https://www.kaggle.com/datasets/olistbr/brazilian-ecommerce
A185: 71ea8340051d1eb026b7f104899eafe9 | B185: 42870.566 | C185: 42872.174 | D185: 42872.685 | E185: 42877.536 | F185: 42895 | G185: SP | H185: Sao Paulo | I185: Computers Accessories | J185: 1 | K185: 207.3 | L185: 16.2 | M185: 5 | N185: =IFERROR(E185-B185,"") -> 6.970544 | O185: =IFERROR(MAX(0,E185-F185),"") -> 0 | P185: =IF(O185>0,"Delayed","On Time") -> On Time | Q185: =IFERROR((C185-B185)*24,"") -> 38.598889 | R185: =IFERROR(D185-C185,"") -> 0.51075231 | S185: =IFERROR(E185-D185,"") -> 4.8515046 | T185: =IF(O185=0,"On Time/Early",IF(O185<=3,"1-3 Days Late",IF(O185<=7,"4-7 Days Late","8+ Days Late"))) -> On Time/Early | U185: =IF(P185="Delayed","Needs Review","Normal") -> Normal | V185: https://www.kaggle.com/datasets/olistbr/brazilian-ecommerce
A186: c3cb4c7c4b963ab08b07a5dca5baf05d | B186: 42870.687 | C186: 42871.149 | D186: 42872.392 | E186: 42878.536 | F186: 42894 | G186: RS | H186: Trindade Do Sul | I186: Stationery | J186: 1 | K186: 119 | L186: 15.58 | M186: 5 | N186: =IFERROR(E186-B186,"") -> 7.849213 | O186: =IFERROR(MAX(0,E186-F186),"") -> 0 | P186: =IF(O186>0,"Delayed","On Time") -> On Time | Q186: =IFERROR((C186-B186)*24,"") -> 11.103611 | R186: =IFERROR(D186-C186,"") -> 1.2427662 | S186: =IFERROR(E186-D186,"") -> 6.1437963 | T186: =IF(O186=0,"On Time/Early",IF(O186<=3,"1-3 Days Late",IF(O186<=7,"4-7 Days Late","8+ Days Late"))) -> On Time/Early | U186: =IF(P186="Delayed","Needs Review","Normal") -> Normal | V186: https://www.kaggle.com/datasets/olistbr/brazilian-ecommerce
A187: 123a6b2b8763ca40782c8252e63fdbca | B187: 42870.718 | C187: 42872.168 | D187: 42877.66 | E187: 42885.644 | F187: 42892 | G187: PR | H187: Campo Mourao | I187: Computers Accessories | J187: 1 | K187: 177 | L187: 17 | M187: 4 | N187: =IFERROR(E187-B187,"") -> 14.926701 | O187: =IFERROR(MAX(0,E187-F187),"") -> 0 | P187: =IF(O187>0,"Delayed","On Time") -> On Time | Q187: =IFERROR((C187-B187)*24,"") -> 34.819722 | R187: =IFERROR(D187-C187,"") -> 5.4911458 | S187: =IFERROR(E187-D187,"") -> 7.9847338 | T187: =IF(O187=0,"On Time/Early",IF(O187<=3,"1-3 Days Late",IF(O187<=7,"4-7 Days Late","8+ Days Late"))) -> On Time/Early | U187: =IF(P187="Delayed","Needs Review","Normal") -> Normal | V187: https://www.kaggle.com/datasets/olistbr/brazilian-ecommerce
A188: c15582dfe92312e48613b9cb37caf0c8 | B188: 42870.76 | C188: 42872.17 | D188: 42873.447 | E188: 42881.332 | F188: 42900 | G188: GO | H188: Carmo Do Rio Verde | I188: Health Beauty | J188: 1 | K188: 89.99 | L188: 15.38 | M188: 5 | N188: =IFERROR(E188-B188,"") -> 10.572685 | O188: =IFERROR(MAX(0,E188-F188),"") -> 0 | P188: =IF(O188>0,"Delayed","On Time") -> On Time | Q188: =IFERROR((C188-B188)*24,"") -> 33.856111 | R188: =IFERROR(D188-C188,"") -> 1.2765278 | S188: =IFERROR(E188-D188,"") -> 7.8854861 | T188: =IF(O188=0,"On Time/Early",IF(O188<=3,"1-3 Days Late",IF(O188<=7,"4-7 Days Late","8+ Days Late"))) -> On Time/Early | U188: =IF(P188="Delayed","Needs Review","Normal") -> Normal | V188: https://www.kaggle.com/datasets/olistbr/brazilian-ecommerce
A189: 04eb8bac62618bbc56c582cd49493669 | B189: 42871.384 | C189: 42871.393 | D189: 42872.633 | E189: 42878.356 | F189: 42900 | G189: RJ | H189: Sao Goncalo | I189: Fashion Bags Accessories | J189: 1 | K189: 69.9 | L189: 14.24 | M189: 4 | N189: =IFERROR(E189-B189,"") -> 6.9723843 | O189: =IFERROR(MAX(0,E189-F189),"") -> 0 | P189: =IF(O189>0,"Delayed","On Time") -> On Time | Q189: =IFERROR((C189-B189)*24,"") -> 0.21083333 | R189: =IFERROR(D189-C189,"") -> 1.2400116 | S189: =IFERROR(E189-D189,"") -> 5.723588 | T189: =IF(O189=0,"On Time/Early",IF(O189<=3,"1-3 Days Late",IF(O189<=7,"4-7 Days Late","8+ Days Late"))) -> On Time/Early | U189: =IF(P189="Delayed","Needs Review","Normal") -> Normal | V189: https://www.kaggle.com/datasets/olistbr/brazilian-ecommerce
A190: 7195bbe2eb284effff29db46278daad8 | B190: 42871.41 | C190: 42872.413 | D190: 42873.641 | E190: 42880.379 | F190: 42899 | G190: RJ | H190: Mesquita | I190: Baby | J190: 1 | K190: 50 | L190: 16.6 | M190: 5 | N190: =IFERROR(E190-B190,"") -> 8.9687731 | O190: =IFERROR(MAX(0,E190-F190),"") -> 0 | P190: =IF(O190>0,"Delayed","On Time") -> On Time | Q190: =IFERROR((C190-B190)*24,"") -> 24.079722 | R190: =IFERROR(D190-C190,"") -> 1.2273495 | S190: =IFERROR(E190-D190,"") -> 6.7381019 | T190: =IF(O190=0,"On Time/Early",IF(O190<=3,"1-3 Days Late",IF(O190<=7,"4-7 Days Late","8+ Days Late"))) -> On Time/Early | U190: =IF(P190="Delayed","Needs Review","Normal") -> Normal | V190: https://www.kaggle.com/datasets/olistbr/brazilian-ecommerce
A191: b9fa782d4918580e25b6e3b516a55710 | B191: 42871.451 | C191: 42871.462 | D191: 42872.625 | E191: 42878.529 | F191: 42892 | G191: SP | H191: Sao Paulo | I191: Bed Bath Table | J191: 1 | K191: 89.9 | L191: 12.13 | M191: 5 | N191: =IFERROR(E191-B191,"") -> 7.0783449 | O191: =IFERROR(MAX(0,E191-F191),"") -> 0 | P191: =IF(O191>0,"Delayed","On Time") -> On Time | Q191: =IFERROR((C191-B191)*24,"") -> 0.26194444 | R191: =IFERROR(D191-C191,"") -> 1.1632523 | S191: =IFERROR(E191-D191,"") -> 5.9041782 | T191: =IF(O191=0,"On Time/Early",IF(O191<=3,"1-3 Days Late",IF(O191<=7,"4-7 Days Late","8+ Days Late"))) -> On Time/Early | U191: =IF(P191="Delayed","Needs Review","Normal") -> Normal | V191: https://www.kaggle.com/datasets/olistbr/brazilian-ecommerce
A192: 45ab65433b358cdb30d0f2af36c96e7c | B192: 42871.525 | C192: 42871.549 | D192: 42872.422 | E192: 42877.572 | F192: 42893 | G192: SP | H192: Sao Paulo | I192: Computers Accessories | J192: 1 | K192: 199.9 | L192: 18.65 | M192: 5 | N192: =IFERROR(E192-B192,"") -> 6.0465046 | O192: =IFERROR(MAX(0,E192-F192),"") -> 0 | P192: =IF(O192>0,"Delayed","On Time") -> On Time | Q192: =IFERROR((C192-B192)*24,"") -> 0.57166667 | R192: =IFERROR(D192-C192,"") -> 0.87327546 | S192: =IFERROR(E192-D192,"") -> 5.1494097 | T192: =IF(O192=0,"On Time/Early",IF(O192<=3,"1-3 Days Late",IF(O192<=7,"4-7 Days Late","8+ Days Late"))) -> On Time/Early | U192: =IF(P192="Delayed","Needs Review","Normal") -> Normal | V192: https://www.kaggle.com/datasets/olistbr/brazilian-ecommerce
A193: c7d3893304861d303bb8f6193525bbf0 | B193: 42871.814 | C193: 42871.823 | D193: 42872.511 | E193: 42878.476 | F193: 42902 | G193: BA | H193: Salvador | I193: Toys | J193: 1 | K193: 145.9 | L193: 18.59 | M193: 5 | N193: =IFERROR(E193-B193,"") -> 6.6621759 | O193: =IFERROR(MAX(0,E193-F193),"") -> 0 | P193: =IF(O193>0,"Delayed","On Time") -> On Time | Q193: =IFERROR((C193-B193)*24,"") -> 0.22333333 | R193: =IFERROR(D193-C193,"") -> 0.68829861 | S193: =IFERROR(E193-D193,"") -> 5.9645718 | T193: =IF(O193=0,"On Time/Early",IF(O193<=3,"1-3 Days Late",IF(O193<=7,"4-7 Days Late","8+ Days Late"))) -> On Time/Early | U193: =IF(P193="Delayed","Needs Review","Normal") -> Normal | V193: https://www.kaggle.com/datasets/olistbr/brazilian-ecommerce
A194: 7ac13b045c748b7eef3f9011bd5683c9 | B194: 42872.735 | C194: 42872.743 | D194: 42873.361 | E194: 42874.437 | F194: 42894 | G194: SP | H194: Cotia | I194: Computers Accessories | J194: 1 | K194: 39.9 | L194: 14.1 | M194: 5 | N194: =IFERROR(E194-B194,"") -> 1.7020486 | O194: =IFERROR(MAX(0,E194-F194),"") -> 0 | P194: =IF(O194>0,"Delayed","On Time") -> On Time | Q194: =IFERROR((C194-B194)*24,"") -> 0.19166667 | R194: =IFERROR(D194-C194,"") -> 0.61789352 | S194: =IFERROR(E194-D194,"") -> 1.076169 | T194: =IF(O194=0,"On Time/Early",IF(O194<=3,"1-3 Days Late",IF(O194<=7,"4-7 Days Late","8+ Days Late"))) -> On Time/Early | U194: =IF(P194="Delayed","Needs Review","Normal") -> Normal | V194: https://www.kaggle.com/datasets/olistbr/brazilian-ecommerce
... A206: a797f338da66eefca816db5328d5e5ab | B206: 42878.631 | C206: 42878.641 | D206: 42879.548 | E206: 42887.478 | F206: 42912 | G206: RS | H206: Campo Bom | I206: Housewares | J206: 3 | K206: 143.97 | L206: 45.33 | M206: 1 | N206: =IFERROR(E206-B206,"") -> 8.8468056 | O206: =IFERROR(MAX(0,E206-F206),"") -> 0 | P206: =IF(O206>0,"Delayed","On Time") -> On Time | Q206: =IFERROR((C206-B206)*24,"") -> 0.24416667 | R206: =IFERROR(D206-C206,"") -> 0.90711806 | S206: =IFERROR(E206-D206,"") -> 7.9295139 | T206: =IF(O206=0,"On Time/Early",IF(O206<=3,"1-3 Days Late",IF(O206<=7,"4-7 Days Late","8+ Days Late"))) -> On Time/Early | U206: =IF(P206="Delayed","Needs Review","Normal") -> Normal | V206: https://www.kaggle.com/datasets/olistbr/brazilian-ecommerce
A207: 42ba338f99f42e0261e5897c7da157c5 | B207: 42878.638 | C207: 42878.649 | D207: 42879.395 | E207: 42886.371 | F207: 42898 | G207: SP | H207: Sao Paulo | I207: Sports Leisure | J207: 1 | K207: 69.9 | L207: 11.99 | N207: =IFERROR(E207-B207,"") -> 7.7321528 | O207: =IFERROR(MAX(0,E207-F207),"") -> 0 | P207: =IF(O207>0,"Delayed","On Time") -> On Time | Q207: =IFERROR((C207-B207)*24,"") -> 0.26583333 | R207: =IFERROR(D207-C207,"") -> 0.74516204 | S207: =IFERROR(E207-D207,"") -> 6.9759144 | T207: =IF(O207=0,"On Time/Early",IF(O207<=3,"1-3 Days Late",IF(O207<=7,"4-7 Days Late","8+ Days Late"))) -> On Time/Early | U207: =IF(P207="Delayed","Needs Review","Normal") -> Normal | V207: https://www.kaggle.com/datasets/olistbr/brazilian-ecommerce
A208: 6311e2bf4ff2a50d88a27f8178ed0282 | B208: 42879.399 | C208: 42879.407 | D208: 42886.453 | E208: 42893.366 | F208: 42892 | G208: SP | H208: Sao Paulo | I208: Cool Stuff | J208: 1 | K208: 129.99 | L208: 12.11 | M208: 3 | N208: =IFERROR(E208-B208,"") -> 13.966562 | O208: =IFERROR(MAX(0,E208-F208),"") -> 1.3656481 | P208: =IF(O208>0,"Delayed","On Time") -> Delayed | Q208: =IFERROR((C208-B208)*24,"") -> 0.17833333 | R208: =IFERROR(D208-C208,"") -> 7.0466782 | S208: =IFERROR(E208-D208,"") -> 6.9124537 | T208: =IF(O208=0,"On Time/Early",IF(O208<=3,"1-3 Days Late",IF(O208<=7,"4-7 Days Late","8+ Days Late"))) -> 1-3 Days Late | U208: =IF(P208="Delayed","Needs Review","Normal") -> Needs Review | V208: https://www.kaggle.com/datasets/olistbr/brazilian-ecommerce
...

Sheet Monthly_Analysis
A1: Monthly Delivery Performance Analysis
A2: Analysis calculated from the full delivered-order dataset. Sparse launch months are flagged in Operational_Note.
A3: Month | B3: Delivered_Orders | C3: On_Time_Orders | D3: Delayed_Orders | E3: Delay_Rate | F3: Avg_Delivery_Days | G3: Avg_Delay_Days | H3: Avg_Review_Score | I3: Avg_Freight | J3: Avg_Items | K3: Operational_Note
A4: 2016-09 | B4: 1 | C4: 0 | D4: 1 | E4: =IFERROR(D4/B4,0) -> 1 | F4: 54.813194 | G4: 36.324745 | H4: 1 | I4: 8.49 | J4: 3 | K4: Low-volume launch month, interpret carefully
A5: 2016-10 | B5: 265 | C5: 262 | D5: 3 | E5: =IFERROR(D5/B5,0) -> 0.011320755 | F5: 19.600559 | G5: 0.078614867 | H5: 4.0114504 | I5: 23.266226 | J5: 1.1811321 | K5: Stable on-time performance
A6: 2016-12 | B6: 1 | C6: 1 | D6: 0 | E6: =IFERROR(D6/B6,0) -> 0 | F6: 4.6930208 | G6: 0 | H6: 5 | I6: 8.72 | J6: 1 | K6: Low-volume launch month, interpret carefully
A7: 2017-01 | B7: 750 | C7: 727 | D7: 23 | E7: =IFERROR(D7/B7,0) -> 0.030666667 | F7: 12.647044 | G7: 0.6086929 | H7: 4.1990553 | I7: 20.912013 | J7: 1.2173333 | K7: Stable on-time performance
A8: 2017-02 | B8: 1653 | C8: 1600 | D8: 53 | E8: =IFERROR(D8/B8,0) -> 0.032062916 | F8: 13.168825 | G8: 0.63256765 | H8: 4.202678 | I8: 22.393176 | J8: 1.1240169 | K8: Stable on-time performance
A9: 2017-03 | B9: 2546 | C9: 2404 | D9: 142 | E9: =IFERROR(D9/B9,0) -> 0.055773763 | F9: 12.951184 | G9: 1.1892369 | H9: 4.1873763 | I9: 21.654399 | J9: 1.1378633 | K9: Monitor trend
A10: 2017-04 | B10: 2303 | C10: 2122 | D10: 181 | E10: =IFERROR(D10/B10,0) -> 0.078593139 | F10: 14.917913 | G10: 0.8499348 | H10: 4.1375546 | I10: 21.772783 | J10: 1.1155015 | K10: Monitor trend
A11: 2017-05 | B11: 3545 | C11: 3417 | D11: 128 | E11: =IFERROR(D11/B11,0) -> 0.036107193 | F11: 11.322363 | G11: 0.39475199 | H11: 4.2382713 | I11: 21.861255 | J11: 1.1291961 | K11: Stable on-time performance
A12: 2017-06 | B12: 3135 | C12: 3014 | D12: 121 | E12: =IFERROR(D12/B12,0) -> 0.038596491 | F12: 12.011573 | G12: 0.45832311 | H12: 4.2229187 | I12: 21.7311 | J12: 1.1129187 | K12: Stable on-time performance
A13: 2017-07 | B13: 3872 | C13: 3739 | D13: 133 | E13: =IFERROR(D13/B13,0) -> 0.034349174 | F13: 11.592732 | G13: 0.35109563 | H13: 4.2584158 | I13: 21.873595 | J13: 1.1404959 | K13: Stable on-time performance
A14: 2017-08 | B14: 4193 | C14: 4054 | D14: 139 | E14: =IFERROR(D14/B14,0) -> 0.033150489 | F14: 11.147125 | G14: 0.27933835 | H14: 4.3115246 | I14: 21.734477 | J14: 1.1440496 | K14: Stable on-time performance
A15: 2017-09 | B15: 4150 | C15: 3934 | D15: 216 | E15: =IFERROR(D15/B15,0) -> 0.052048193 | F15: 11.851007 | G15: 0.45017719 | H15: 4.2674842 | I15: 22.572969 | J15: 1.1414458 | K15: Monitor trend
... A26: 2018-08 | B26: 6351 | C26: 5691 | D26: 660 | E26: =IFERROR(D26/B26,0) -> 0.10392064 | F26: 7.7327797 | G26: 0.34108024 | H26: 4.3103476 | I26: 23.132578 | J26: 1.1245473 | K26: Delay spike: investigate capacity/carrier issues

Sheet State_Analysis
A1: State-Level Delay Hotspots
A2: Top 15 states ranked by delayed order count, with priority based on delay rate and volume.
A3: State | B3: Delivered_Orders | C3: On_Time_Orders | D3: Delayed_Orders | E3: Delay_Rate | F3: Avg_Delivery_Days | G3: Avg_Delay_Days | H3: Avg_Review_Score | I3: Avg_Freight | J3: Priority | K3: Recommended_Action
A4: SP | B4: 40494 | C4: 38107 | D4: 2387 | E4: =IFERROR(D4/B4,0) -> 0.058947004 | F4: 8.761386 | G4: 0.41426975 | H4: 4.246519 | I4: 17.334797 | J4: High | K4: Review carrier SLAs and escalation rules
A5: RJ | B5: 12350 | C5: 10686 | D5: 1664 | E5: =IFERROR(D5/B5,0) -> 0.13473684 | F5: 15.309438 | G5: 1.7311922 | H5: 3.9651407 | I5: 23.947404 | J5: High | K5: Review carrier SLAs and escalation rules
A6: MG | B6: 11354 | C6: 10717 | D6: 637 | E6: =IFERROR(D6/B6,0) -> 0.056103576 | F6: 12.008666 | G6: 0.42235072 | H6: 4.1924679 | I6: 23.463963 | J6: High | K6: Review carrier SLAs and escalation rules
A7: BA | B7: 3256 | C7: 2799 | D7: 457 | E7: =IFERROR(D7/B7,0) -> 0.14035627 | F7: 19.335466 | G7: 1.5578454 | H7: 3.9300093 | I7: 29.961201 | J7: High | K7: Review carrier SLAs and escalation rules
A8: RS | B8: 5344 | C8: 4962 | D8: 382 | E8: =IFERROR(D8/B8,0) -> 0.071482036 | F8: 15.300276 | G8: 0.67247095 | H8: 4.1855989 | I8: 24.805449 | J8: Medium | K8: Monitor weekly and check peak periods
A9: SC | B9: 3546 | C9: 3200 | D9: 346 | E9: =IFERROR(D9/B9,0) -> 0.097574732 | F9: 14.954783 | G9: 0.75136649 | H9: 4.1332765 | I9: 24.849309 | J9: Medium | K9: Monitor weekly and check peak periods
A10: PR | B10: 4923 | C10: 4677 | D10: 246 | E10: =IFERROR(D10/B10,0) -> 0.049969531 | F10: 11.991582 | G10: 0.36977923 | H10: 4.2395918 | I10: 23.490817 | J10: Low | K10: Maintain current process
A11: ES | B11: 1995 | C11: 1751 | D11: 244 | E11: =IFERROR(D11/B11,0) -> 0.12230576 | F11: 15.789307 | G11: 1.2959719 | H11: 4.0797359 | I11: 24.568662 | J11: High | K11: Review carrier SLAs and escalation rules
A12: CE | B12: 1279 | C12: 1083 | D12: 196 | E12: =IFERROR(D12/B12,0) -> 0.15324472 | F12: 21.266579 | G12: 2.1955046 | H12: 3.9418696 | I12: 36.496787 | J12: High | K12: Review carrier SLAs and escalation rules
A13: PE | B13: 1593 | C13: 1421 | D13: 172 | E13: =IFERROR(D13/B13,0) -> 0.10797238 | F13: 18.448323 | G13: 1.2248001 | H13: 4.0829639 | I13: 35.833371 | J13: High | K13: Review carrier SLAs and escalation rules
A14: GO | B14: 1957 | C14: 1797 | D14: 160 | E14: =IFERROR(D14/B14,0) -> 0.081757793 | F14: 15.606339 | G14: 0.80026352 | H14: 4.1043165 | I14: 26.252248 | J14: Medium | K14: Monitor weekly and check peak periods
A15: DF | B15: 2080 | C15: 1933 | D15: 147 | E15: =IFERROR(D15/B15,0) -> 0.070673077 | F15: 12.967568 | G15: 0.46918566 | H15: 4.1338164 | I15: 23.858144 | J15: Medium | K15: Monitor weekly and check peak periods
... A18: AL | B18: 397 | C18: 302 | D18: 95 | E18: =IFERROR(D18/B18,0) -> 0.23929471 | F18: 24.543855 | G18: 2.2125499 | H18: 3.8527919 | I18: 38.581285 | J18: High | K18: Review carrier SLAs and escalation rules

Sheet Category_Analysis
A1: Product Category Delay Risk Analysis
A2: Top 15 product categories among categories with at least 200 delivered orders, ranked by delay rate.
A3: Category | B3: Delivered_Orders | C3: On_Time_Orders | D3: Delayed_Orders | E3: Delay_Rate | F3: Avg_Delivery_Days | G3: Avg_Delay_Days | H3: Avg_Review_Score | I3: Avg_Freight | J3: Priority | K3: Recommended_Action
A4: Audio | B4: 344 | C4: 299 | D4: 45 | E4: =IFERROR(D4/B4,0) -> 0.13081395 | F4: 13.506538 | G4: 1.0908512 | H4: 3.8460411 | I4: 16.441773 | J4: High | K4: Audit category packaging, supplier readiness, and carrier handoff
A5: Books Technical | B5: 255 | C5: 227 | D5: 28 | E5: =IFERROR(D5/B5,0) -> 0.10980392 | F5: 10.644328 | G5: 0.60594485 | H5: 4.4251969 | I5: 16.607216 | J5: High | K5: Audit category packaging, supplier readiness, and carrier handoff
A6: Home Confort | B6: 367 | C6: 329 | D6: 38 | E6: =IFERROR(D6/B6,0) -> 0.10354223 | F6: 13.576062 | G6: 1.3681457 | H6: 3.909589 | I6: 23.226131 | J6: High | K6: Audit category packaging, supplier readiness, and carrier handoff
A7: Food | B7: 436 | C7: 392 | D7: 44 | E7: =IFERROR(D7/B7,0) -> 0.10091743 | F7: 9.8160277 | G7: 1.0577255 | H7: 4.3240741 | I7: 16.114908 | J7: High | K7: Audit category packaging, supplier readiness, and carrier handoff
A8: Electronics | B8: 2507 | C8: 2260 | D8: 247 | E8: =IFERROR(D8/B8,0) -> 0.098524132 | F8: 12.936072 | G8: 0.78279142 | H8: 4.1290193 | I8: 18.351005 | J8: Medium | K8: Monitor during high-volume weeks
A9: Baby | B9: 2764 | C9: 2506 | D9: 258 | E9: =IFERROR(D9/B9,0) -> 0.093342981 | F9: 12.731318 | G9: 0.99874722 | H9: 4.1208972 | I9: 24.031422 | J9: Medium | K9: Monitor during high-volume weeks
A10: Office Furniture | B10: 1246 | C10: 1131 | D10: 115 | E10: =IFERROR(D10/B10,0) -> 0.092295345 | F10: 20.702587 | G10: 1.1346767 | H10: 3.6500809 | I10: 53.578483 | J10: Medium | K10: Monitor during high-volume weeks
A11: Construction Tools Construction | B11: 727 | C11: 660 | D11: 67 | E11: =IFERROR(D11/B11,0) -> 0.09215956 | F11: 10.86961 | G11: 0.95266161 | H11: 4.1308864 | I11: 28.01414 | J11: Medium | K11: Monitor during high-volume weeks
A12: Construction Tools Lights | B12: 232 | C12: 211 | D12: 21 | E12: =IFERROR(D12/B12,0) -> 0.090517241 | F12: 9.7490544 | G12: 0.4638633 | H12: 4.2008734 | I12: 32.097759 | J12: Medium | K12: Monitor during high-volume weeks
A13: Health Beauty | B13: 8610 | C13: 7836 | D13: 774 | E13: =IFERROR(D13/B13,0) -> 0.08989547 | F13: 12.098038 | G13: 0.80372171 | H13: 4.2353846 | I13: 20.779994 | J13: Medium | K13: Monitor during high-volume weeks
A14: Unknown | B14: 1355 | C14: 1234 | D14: 121 | E14: =IFERROR(D14/B14,0) -> 0.089298893 | F14: 12.749703 | G14: 0.81584978 | H14: 4.0375186 | I14: 19.461506 | J14: Medium | K14: Monitor during high-volume weeks
A15: Musical Instruments | B15: 608 | C15: 554 | D15: 54 | E15: =IFERROR(D15/B15,0) -> 0.088815789 | F15: 13.115038 | G15: 0.99946251 | H15: 4.2425249 | I15: 29.498882 | J15: Medium | K15: Monitor during high-volume weeks
... A18: Furniture Living Room | B18: 409 | C18: 374 | D18: 35 | E18: =IFERROR(D18/B18,0) -> 0.085574572 | F18: 13.945042 | G18: 0.86609934 | H18: 4.0940594 | I18: 43.642152 | J18: Medium | K18: Monitor during high-volume weeks

Sheet Data_Source_Methodology
A1: Data Source and Methodology
A3: Section | B3: Details
A4: Project objective | B4: Analyze operational delivery performance using public e-commerce data, identify delay patterns, and recommend practical process improvements.
A5: Primary public dataset | B5: Olist Brazilian E-Commerce Public Dataset by Olist. The dataset contains anonymized e-commerce orders from Brazil across orders, items, customers, products, reviews, payments, sellers, and geolocation tables.
A6: Source URL | B6: https://www.kaggle.com/datasets/olistbr/brazilian-ecommerce
A7: GitHub mirror used for CSV access | B7: https://github.com/Ganesh7699/Brazilian-E-Commerce-OList
A8: Tables used | B8: olist_orders_dataset.csv, olist_customers_dataset.csv, olist_order_items_dataset.csv, olist_order_reviews_dataset.csv, olist_products_dataset.csv, product_category_name_translation.csv
A9: Data cleaning steps | B9: Filtered delivered orders with valid purchase, estimated delivery, and actual delivery dates; joined customers for location; joined order items for product value, freight, item count, and category; joined reviews for review score; translated product categories into English.
A10: KPI definitions | B10: Delay Days = max(0, Delivered Date - Estimated Date). Delay Rate = Delayed Orders / Delivered Orders. Delivery Days = Delivered Date - Purchase Date. On-Time Orders = delivered on or before estimated date.
A11: Analysis methods | B11: Monthly trend analysis, state-level delay hotspot analysis, category risk analysis, delivery duration calculations, SLA bucket classification, review-score comparison, and chart-based dashboarding.
A12: Interpretation note | B12: Raw_Data_Sample contains a representative sample of 2,000 joined delivered orders for transparency and editable formulas. The summary analysis tables were calculated from the full delivered-order dataset.
A13: Recommended tools | B13: Excel or Google Sheets for filtering, formulas, charts, and dashboard review. Power BI can also be used if a more interactive version is needed.

Sheet Recommendations
A1: Operational Recommendations and Action Plan
A3: Priority | B3: Recommendation | C3: Evidence | D3: Expected Operational Benefit | E3: Owner | F3: Suggested KPI | G3: Timeframe | H3: Status
A4: High | B4: Create a weekly delivery delay dashboard by state. | C4: RJ and BA show higher delay rates than the overall average. | D4: Faster visibility of late delivery risk and better escalation before customer complaints. | E4: Operations Analyst / Logistics Lead | F4: Delay Rate by State | G4: 2 weeks | H4: Ready
A5: High | B5: Introduce exception alerts for orders at risk of missing estimated delivery dates. | C5: Delayed orders are concentrated in specific periods and regions. | D5: Reduces reactive follow-up and improves customer communication. | E5: Operations Specialist | F5: Orders At Risk | G5: 2-4 weeks | H5: Ready
A6: Medium | B6: Review carrier SLA performance in high-delay states. | C6: States with higher average delivery days also show higher delay rates. | D6: Better route planning, carrier accountability, and escalation. | E6: Logistics Coordinator | F6: Carrier On-Time Rate | G6: 1 month | H6: Ready
A7: Medium | B7: Audit categories with high delay rates for packaging and handling complexity. | C7: Audio, Home Comfort, Food, and Electronics have elevated delay rates in this analysis. | D7: Reduces category-specific bottlenecks and improves fulfillment consistency. | E7: Warehouse / Fulfillment Team | F7: Category Delay Rate | G7: 1 month | H7: Ready
A8: Medium | B8: Track customer review score beside delivery KPIs. | C8: Review scores are a useful customer experience signal after delivery. | D8: Connects operational performance with customer satisfaction outcomes. | E8: Customer Success + Operations | F8: Review Score by Delay Status | G8: 2 weeks | H8: Ready
A9: Low | B9: Standardize a monthly operations report template. | C9: Monthly delay rates show useful trends for decision-making. | D9: Creates repeatable reporting and supports better management communication. | E9: Operations Assistant | F9: Monthly KPI Completion | G9: Ongoing | H9: Ready
